{
 "cells": [
  {
   "cell_type": "code",
   "execution_count": 19,
   "id": "927a6f54",
   "metadata": {},
   "outputs": [
    {
     "name": "stderr",
     "output_type": "stream",
     "text": [
      "Exception in Tkinter callback\n",
      "Traceback (most recent call last):\n",
      "  File \"D:\\Anaconda\\lib\\tkinter\\__init__.py\", line 1892, in __call__\n",
      "    return self.func(*args)\n",
      "  File \"C:\\Users\\yako_\\AppData\\Local\\Temp\\ipykernel_11484\\1218884212.py\", line 76, in <lambda>\n",
      "    classify_b=Button(top,text=\"Classify Image\",command=lambda: classify(file_path),padx=10,pady=5)\n",
      "  File \"C:\\Users\\yako_\\AppData\\Local\\Temp\\ipykernel_11484\\1218884212.py\", line 70, in classify\n",
      "    pred = np.argmax(model.predict(image),axis=1)\n",
      "  File \"D:\\Anaconda\\lib\\site-packages\\keras\\utils\\traceback_utils.py\", line 70, in error_handler\n",
      "    raise e.with_traceback(filtered_tb) from None\n",
      "  File \"C:\\Users\\yako_\\AppData\\Local\\Temp\\__autograph_generated_file1oq_wkcp.py\", line 15, in tf__predict_function\n",
      "    retval_ = ag__.converted_call(ag__.ld(step_function), (ag__.ld(self), ag__.ld(iterator)), None, fscope)\n",
      "ValueError: in user code:\n",
      "\n",
      "    File \"D:\\Anaconda\\lib\\site-packages\\keras\\engine\\training.py\", line 2041, in predict_function  *\n",
      "        return step_function(self, iterator)\n",
      "    File \"D:\\Anaconda\\lib\\site-packages\\keras\\engine\\training.py\", line 2027, in step_function  **\n",
      "        outputs = model.distribute_strategy.run(run_step, args=(data,))\n",
      "    File \"D:\\Anaconda\\lib\\site-packages\\keras\\engine\\training.py\", line 2015, in run_step  **\n",
      "        outputs = model.predict_step(data)\n",
      "    File \"D:\\Anaconda\\lib\\site-packages\\keras\\engine\\training.py\", line 1983, in predict_step\n",
      "        return self(x, training=False)\n",
      "    File \"D:\\Anaconda\\lib\\site-packages\\keras\\utils\\traceback_utils.py\", line 70, in error_handler\n",
      "        raise e.with_traceback(filtered_tb) from None\n",
      "    File \"D:\\Anaconda\\lib\\site-packages\\keras\\engine\\input_spec.py\", line 295, in assert_input_compatibility\n",
      "        raise ValueError(\n",
      "\n",
      "    ValueError: Input 0 of layer \"sequential_1\" is incompatible with the layer: expected shape=(None, 32, 32, 3), found shape=(None, 32, 32, 4)\n",
      "\n",
      "Exception in Tkinter callback\n",
      "Traceback (most recent call last):\n",
      "  File \"D:\\Anaconda\\lib\\tkinter\\__init__.py\", line 1892, in __call__\n",
      "    return self.func(*args)\n",
      "  File \"C:\\Users\\yako_\\AppData\\Local\\Temp\\ipykernel_11484\\1218884212.py\", line 76, in <lambda>\n",
      "    classify_b=Button(top,text=\"Classify Image\",command=lambda: classify(file_path),padx=10,pady=5)\n",
      "  File \"C:\\Users\\yako_\\AppData\\Local\\Temp\\ipykernel_11484\\1218884212.py\", line 70, in classify\n",
      "    pred = np.argmax(model.predict(image),axis=1)\n",
      "  File \"D:\\Anaconda\\lib\\site-packages\\keras\\utils\\traceback_utils.py\", line 70, in error_handler\n",
      "    raise e.with_traceback(filtered_tb) from None\n",
      "  File \"C:\\Users\\yako_\\AppData\\Local\\Temp\\__autograph_generated_file1oq_wkcp.py\", line 15, in tf__predict_function\n",
      "    retval_ = ag__.converted_call(ag__.ld(step_function), (ag__.ld(self), ag__.ld(iterator)), None, fscope)\n",
      "ValueError: in user code:\n",
      "\n",
      "    File \"D:\\Anaconda\\lib\\site-packages\\keras\\engine\\training.py\", line 2041, in predict_function  *\n",
      "        return step_function(self, iterator)\n",
      "    File \"D:\\Anaconda\\lib\\site-packages\\keras\\engine\\training.py\", line 2027, in step_function  **\n",
      "        outputs = model.distribute_strategy.run(run_step, args=(data,))\n",
      "    File \"D:\\Anaconda\\lib\\site-packages\\keras\\engine\\training.py\", line 2015, in run_step  **\n",
      "        outputs = model.predict_step(data)\n",
      "    File \"D:\\Anaconda\\lib\\site-packages\\keras\\engine\\training.py\", line 1983, in predict_step\n",
      "        return self(x, training=False)\n",
      "    File \"D:\\Anaconda\\lib\\site-packages\\keras\\utils\\traceback_utils.py\", line 70, in error_handler\n",
      "        raise e.with_traceback(filtered_tb) from None\n",
      "    File \"D:\\Anaconda\\lib\\site-packages\\keras\\engine\\input_spec.py\", line 295, in assert_input_compatibility\n",
      "        raise ValueError(\n",
      "\n",
      "    ValueError: Input 0 of layer \"sequential_1\" is incompatible with the layer: expected shape=(None, 32, 32, 3), found shape=(None, 32, 32, 4)\n",
      "\n"
     ]
    },
    {
     "name": "stdout",
     "output_type": "stream",
     "text": [
      "1/1 [==============================] - 0s 203ms/step\n",
      "Children crossing\n",
      "1/1 [==============================] - 0s 32ms/step\n",
      "Children crossing\n",
      "1/1 [==============================] - 0s 32ms/step\n",
      "Children crossing\n"
     ]
    },
    {
     "name": "stderr",
     "output_type": "stream",
     "text": [
      "Exception in Tkinter callback\n",
      "Traceback (most recent call last):\n",
      "  File \"D:\\Anaconda\\lib\\tkinter\\__init__.py\", line 1892, in __call__\n",
      "    return self.func(*args)\n",
      "  File \"C:\\Users\\yako_\\AppData\\Local\\Temp\\ipykernel_11484\\1218884212.py\", line 76, in <lambda>\n",
      "    classify_b=Button(top,text=\"Classify Image\",command=lambda: classify(file_path),padx=10,pady=5)\n",
      "  File \"C:\\Users\\yako_\\AppData\\Local\\Temp\\ipykernel_11484\\1218884212.py\", line 70, in classify\n",
      "    pred = np.argmax(model.predict(image),axis=1)\n",
      "  File \"D:\\Anaconda\\lib\\site-packages\\keras\\utils\\traceback_utils.py\", line 70, in error_handler\n",
      "    raise e.with_traceback(filtered_tb) from None\n",
      "  File \"D:\\Anaconda\\lib\\site-packages\\tensorflow\\python\\eager\\execute.py\", line 54, in quick_execute\n",
      "    tensors = pywrap_tfe.TFE_Py_Execute(ctx._handle, device_name, op_name,\n",
      "tensorflow.python.framework.errors_impl.InvalidArgumentError: Graph execution error:\n",
      "\n",
      "Detected at node 'sequential_1/conv2d_4/Relu' defined at (most recent call last):\n",
      "    File \"D:\\Anaconda\\lib\\runpy.py\", line 197, in _run_module_as_main\n",
      "      return _run_code(code, main_globals, None,\n",
      "    File \"D:\\Anaconda\\lib\\runpy.py\", line 87, in _run_code\n",
      "      exec(code, run_globals)\n",
      "    File \"D:\\Anaconda\\lib\\site-packages\\ipykernel_launcher.py\", line 16, in <module>\n",
      "      app.launch_new_instance()\n",
      "    File \"D:\\Anaconda\\lib\\site-packages\\traitlets\\config\\application.py\", line 846, in launch_instance\n",
      "      app.start()\n",
      "    File \"D:\\Anaconda\\lib\\site-packages\\ipykernel\\kernelapp.py\", line 677, in start\n",
      "      self.io_loop.start()\n",
      "    File \"D:\\Anaconda\\lib\\site-packages\\tornado\\platform\\asyncio.py\", line 199, in start\n",
      "      self.asyncio_loop.run_forever()\n",
      "    File \"D:\\Anaconda\\lib\\asyncio\\base_events.py\", line 601, in run_forever\n",
      "      self._run_once()\n",
      "    File \"D:\\Anaconda\\lib\\asyncio\\base_events.py\", line 1905, in _run_once\n",
      "      handle._run()\n",
      "    File \"D:\\Anaconda\\lib\\asyncio\\events.py\", line 80, in _run\n",
      "      self._context.run(self._callback, *self._args)\n",
      "    File \"D:\\Anaconda\\lib\\site-packages\\ipykernel\\kernelbase.py\", line 471, in dispatch_queue\n",
      "      await self.process_one()\n",
      "    File \"D:\\Anaconda\\lib\\site-packages\\ipykernel\\kernelbase.py\", line 460, in process_one\n",
      "      await dispatch(*args)\n",
      "    File \"D:\\Anaconda\\lib\\site-packages\\ipykernel\\kernelbase.py\", line 367, in dispatch_shell\n",
      "      await result\n",
      "    File \"D:\\Anaconda\\lib\\site-packages\\ipykernel\\kernelbase.py\", line 662, in execute_request\n",
      "      reply_content = await reply_content\n",
      "    File \"D:\\Anaconda\\lib\\site-packages\\ipykernel\\ipkernel.py\", line 360, in do_execute\n",
      "      res = shell.run_cell(code, store_history=store_history, silent=silent)\n",
      "    File \"D:\\Anaconda\\lib\\site-packages\\ipykernel\\zmqshell.py\", line 532, in run_cell\n",
      "      return super().run_cell(*args, **kwargs)\n",
      "    File \"D:\\Anaconda\\lib\\site-packages\\IPython\\core\\interactiveshell.py\", line 2863, in run_cell\n",
      "      result = self._run_cell(\n",
      "    File \"D:\\Anaconda\\lib\\site-packages\\IPython\\core\\interactiveshell.py\", line 2909, in _run_cell\n",
      "      return runner(coro)\n",
      "    File \"D:\\Anaconda\\lib\\site-packages\\IPython\\core\\async_helpers.py\", line 129, in _pseudo_sync_runner\n",
      "      coro.send(None)\n",
      "    File \"D:\\Anaconda\\lib\\site-packages\\IPython\\core\\interactiveshell.py\", line 3106, in run_cell_async\n",
      "      has_raised = await self.run_ast_nodes(code_ast.body, cell_name,\n",
      "    File \"D:\\Anaconda\\lib\\site-packages\\IPython\\core\\interactiveshell.py\", line 3309, in run_ast_nodes\n",
      "      if await self.run_code(code, result, async_=asy):\n",
      "    File \"D:\\Anaconda\\lib\\site-packages\\IPython\\core\\interactiveshell.py\", line 3369, in run_code\n",
      "      exec(code_obj, self.user_global_ns, self.user_ns)\n",
      "    File \"C:\\Users\\yako_\\AppData\\Local\\Temp\\ipykernel_11484\\1218884212.py\", line 104, in <cell line: 104>\n",
      "      top.mainloop()\n",
      "    File \"D:\\Anaconda\\lib\\tkinter\\__init__.py\", line 1429, in mainloop\n",
      "      self.tk.mainloop(n)\n",
      "    File \"D:\\Anaconda\\lib\\tkinter\\__init__.py\", line 1892, in __call__\n",
      "      return self.func(*args)\n",
      "    File \"C:\\Users\\yako_\\AppData\\Local\\Temp\\ipykernel_11484\\1218884212.py\", line 76, in <lambda>\n",
      "      classify_b=Button(top,text=\"Classify Image\",command=lambda: classify(file_path),padx=10,pady=5)\n",
      "    File \"C:\\Users\\yako_\\AppData\\Local\\Temp\\ipykernel_11484\\1218884212.py\", line 70, in classify\n",
      "      pred = np.argmax(model.predict(image),axis=1)\n",
      "    File \"D:\\Anaconda\\lib\\site-packages\\keras\\utils\\traceback_utils.py\", line 65, in error_handler\n",
      "      return fn(*args, **kwargs)\n",
      "    File \"D:\\Anaconda\\lib\\site-packages\\keras\\engine\\training.py\", line 2253, in predict\n",
      "      tmp_batch_outputs = self.predict_function(iterator)\n",
      "    File \"D:\\Anaconda\\lib\\site-packages\\keras\\engine\\training.py\", line 2041, in predict_function\n",
      "      return step_function(self, iterator)\n",
      "    File \"D:\\Anaconda\\lib\\site-packages\\keras\\engine\\training.py\", line 2027, in step_function\n",
      "      outputs = model.distribute_strategy.run(run_step, args=(data,))\n",
      "    File \"D:\\Anaconda\\lib\\site-packages\\keras\\engine\\training.py\", line 2015, in run_step\n",
      "      outputs = model.predict_step(data)\n",
      "    File \"D:\\Anaconda\\lib\\site-packages\\keras\\engine\\training.py\", line 1983, in predict_step\n",
      "      return self(x, training=False)\n",
      "    File \"D:\\Anaconda\\lib\\site-packages\\keras\\utils\\traceback_utils.py\", line 65, in error_handler\n",
      "      return fn(*args, **kwargs)\n",
      "    File \"D:\\Anaconda\\lib\\site-packages\\keras\\engine\\training.py\", line 557, in __call__\n",
      "      return super().__call__(*args, **kwargs)\n",
      "    File \"D:\\Anaconda\\lib\\site-packages\\keras\\utils\\traceback_utils.py\", line 65, in error_handler\n",
      "      return fn(*args, **kwargs)\n",
      "    File \"D:\\Anaconda\\lib\\site-packages\\keras\\engine\\base_layer.py\", line 1097, in __call__\n",
      "      outputs = call_fn(inputs, *args, **kwargs)\n",
      "    File \"D:\\Anaconda\\lib\\site-packages\\keras\\utils\\traceback_utils.py\", line 96, in error_handler\n",
      "      return fn(*args, **kwargs)\n",
      "    File \"D:\\Anaconda\\lib\\site-packages\\keras\\engine\\sequential.py\", line 410, in call\n",
      "      return super().call(inputs, training=training, mask=mask)\n",
      "    File \"D:\\Anaconda\\lib\\site-packages\\keras\\engine\\functional.py\", line 510, in call\n",
      "      return self._run_internal_graph(inputs, training=training, mask=mask)\n",
      "    File \"D:\\Anaconda\\lib\\site-packages\\keras\\engine\\functional.py\", line 667, in _run_internal_graph\n",
      "      outputs = node.layer(*args, **kwargs)\n",
      "    File \"D:\\Anaconda\\lib\\site-packages\\keras\\utils\\traceback_utils.py\", line 65, in error_handler\n",
      "      return fn(*args, **kwargs)\n",
      "    File \"D:\\Anaconda\\lib\\site-packages\\keras\\engine\\base_layer.py\", line 1097, in __call__\n",
      "      outputs = call_fn(inputs, *args, **kwargs)\n",
      "    File \"D:\\Anaconda\\lib\\site-packages\\keras\\utils\\traceback_utils.py\", line 96, in error_handler\n",
      "      return fn(*args, **kwargs)\n",
      "    File \"D:\\Anaconda\\lib\\site-packages\\keras\\layers\\convolutional\\base_conv.py\", line 314, in call\n",
      "      return self.activation(outputs)\n",
      "    File \"D:\\Anaconda\\lib\\site-packages\\keras\\activations.py\", line 317, in relu\n",
      "      return backend.relu(\n",
      "    File \"D:\\Anaconda\\lib\\site-packages\\keras\\backend.py\", line 5366, in relu\n",
      "      x = tf.nn.relu(x)\n",
      "Node: 'sequential_1/conv2d_4/Relu'\n",
      "input must be 4-dimensional[1,32,32]\n",
      "\t [[{{node sequential_1/conv2d_4/Relu}}]] [Op:__inference_predict_function_12822]\n",
      "Exception in Tkinter callback\n",
      "Traceback (most recent call last):\n",
      "  File \"D:\\Anaconda\\lib\\tkinter\\__init__.py\", line 1892, in __call__\n",
      "    return self.func(*args)\n",
      "  File \"C:\\Users\\yako_\\AppData\\Local\\Temp\\ipykernel_11484\\1218884212.py\", line 76, in <lambda>\n",
      "    classify_b=Button(top,text=\"Classify Image\",command=lambda: classify(file_path),padx=10,pady=5)\n",
      "  File \"C:\\Users\\yako_\\AppData\\Local\\Temp\\ipykernel_11484\\1218884212.py\", line 70, in classify\n",
      "    pred = np.argmax(model.predict(image),axis=1)\n",
      "  File \"D:\\Anaconda\\lib\\site-packages\\keras\\utils\\traceback_utils.py\", line 70, in error_handler\n",
      "    raise e.with_traceback(filtered_tb) from None\n",
      "  File \"D:\\Anaconda\\lib\\site-packages\\tensorflow\\python\\eager\\execute.py\", line 54, in quick_execute\n",
      "    tensors = pywrap_tfe.TFE_Py_Execute(ctx._handle, device_name, op_name,\n",
      "tensorflow.python.framework.errors_impl.InvalidArgumentError: Graph execution error:\n",
      "\n",
      "Detected at node 'sequential_1/conv2d_4/Relu' defined at (most recent call last):\n",
      "    File \"D:\\Anaconda\\lib\\runpy.py\", line 197, in _run_module_as_main\n",
      "      return _run_code(code, main_globals, None,\n",
      "    File \"D:\\Anaconda\\lib\\runpy.py\", line 87, in _run_code\n",
      "      exec(code, run_globals)\n",
      "    File \"D:\\Anaconda\\lib\\site-packages\\ipykernel_launcher.py\", line 16, in <module>\n",
      "      app.launch_new_instance()\n",
      "    File \"D:\\Anaconda\\lib\\site-packages\\traitlets\\config\\application.py\", line 846, in launch_instance\n",
      "      app.start()\n",
      "    File \"D:\\Anaconda\\lib\\site-packages\\ipykernel\\kernelapp.py\", line 677, in start\n",
      "      self.io_loop.start()\n",
      "    File \"D:\\Anaconda\\lib\\site-packages\\tornado\\platform\\asyncio.py\", line 199, in start\n",
      "      self.asyncio_loop.run_forever()\n",
      "    File \"D:\\Anaconda\\lib\\asyncio\\base_events.py\", line 601, in run_forever\n",
      "      self._run_once()\n",
      "    File \"D:\\Anaconda\\lib\\asyncio\\base_events.py\", line 1905, in _run_once\n",
      "      handle._run()\n",
      "    File \"D:\\Anaconda\\lib\\asyncio\\events.py\", line 80, in _run\n",
      "      self._context.run(self._callback, *self._args)\n",
      "    File \"D:\\Anaconda\\lib\\site-packages\\ipykernel\\kernelbase.py\", line 471, in dispatch_queue\n",
      "      await self.process_one()\n",
      "    File \"D:\\Anaconda\\lib\\site-packages\\ipykernel\\kernelbase.py\", line 460, in process_one\n",
      "      await dispatch(*args)\n",
      "    File \"D:\\Anaconda\\lib\\site-packages\\ipykernel\\kernelbase.py\", line 367, in dispatch_shell\n",
      "      await result\n",
      "    File \"D:\\Anaconda\\lib\\site-packages\\ipykernel\\kernelbase.py\", line 662, in execute_request\n",
      "      reply_content = await reply_content\n",
      "    File \"D:\\Anaconda\\lib\\site-packages\\ipykernel\\ipkernel.py\", line 360, in do_execute\n",
      "      res = shell.run_cell(code, store_history=store_history, silent=silent)\n",
      "    File \"D:\\Anaconda\\lib\\site-packages\\ipykernel\\zmqshell.py\", line 532, in run_cell\n",
      "      return super().run_cell(*args, **kwargs)\n",
      "    File \"D:\\Anaconda\\lib\\site-packages\\IPython\\core\\interactiveshell.py\", line 2863, in run_cell\n",
      "      result = self._run_cell(\n",
      "    File \"D:\\Anaconda\\lib\\site-packages\\IPython\\core\\interactiveshell.py\", line 2909, in _run_cell\n",
      "      return runner(coro)\n",
      "    File \"D:\\Anaconda\\lib\\site-packages\\IPython\\core\\async_helpers.py\", line 129, in _pseudo_sync_runner\n",
      "      coro.send(None)\n",
      "    File \"D:\\Anaconda\\lib\\site-packages\\IPython\\core\\interactiveshell.py\", line 3106, in run_cell_async\n",
      "      has_raised = await self.run_ast_nodes(code_ast.body, cell_name,\n",
      "    File \"D:\\Anaconda\\lib\\site-packages\\IPython\\core\\interactiveshell.py\", line 3309, in run_ast_nodes\n",
      "      if await self.run_code(code, result, async_=asy):\n",
      "    File \"D:\\Anaconda\\lib\\site-packages\\IPython\\core\\interactiveshell.py\", line 3369, in run_code\n",
      "      exec(code_obj, self.user_global_ns, self.user_ns)\n",
      "    File \"C:\\Users\\yako_\\AppData\\Local\\Temp\\ipykernel_11484\\1218884212.py\", line 104, in <cell line: 104>\n",
      "      top.mainloop()\n",
      "    File \"D:\\Anaconda\\lib\\tkinter\\__init__.py\", line 1429, in mainloop\n",
      "      self.tk.mainloop(n)\n",
      "    File \"D:\\Anaconda\\lib\\tkinter\\__init__.py\", line 1892, in __call__\n",
      "      return self.func(*args)\n",
      "    File \"C:\\Users\\yako_\\AppData\\Local\\Temp\\ipykernel_11484\\1218884212.py\", line 76, in <lambda>\n",
      "      classify_b=Button(top,text=\"Classify Image\",command=lambda: classify(file_path),padx=10,pady=5)\n",
      "    File \"C:\\Users\\yako_\\AppData\\Local\\Temp\\ipykernel_11484\\1218884212.py\", line 70, in classify\n",
      "      pred = np.argmax(model.predict(image),axis=1)\n",
      "    File \"D:\\Anaconda\\lib\\site-packages\\keras\\utils\\traceback_utils.py\", line 65, in error_handler\n",
      "      return fn(*args, **kwargs)\n",
      "    File \"D:\\Anaconda\\lib\\site-packages\\keras\\engine\\training.py\", line 2253, in predict\n",
      "      tmp_batch_outputs = self.predict_function(iterator)\n",
      "    File \"D:\\Anaconda\\lib\\site-packages\\keras\\engine\\training.py\", line 2041, in predict_function\n",
      "      return step_function(self, iterator)\n",
      "    File \"D:\\Anaconda\\lib\\site-packages\\keras\\engine\\training.py\", line 2027, in step_function\n",
      "      outputs = model.distribute_strategy.run(run_step, args=(data,))\n",
      "    File \"D:\\Anaconda\\lib\\site-packages\\keras\\engine\\training.py\", line 2015, in run_step\n",
      "      outputs = model.predict_step(data)\n",
      "    File \"D:\\Anaconda\\lib\\site-packages\\keras\\engine\\training.py\", line 1983, in predict_step\n",
      "      return self(x, training=False)\n",
      "    File \"D:\\Anaconda\\lib\\site-packages\\keras\\utils\\traceback_utils.py\", line 65, in error_handler\n",
      "      return fn(*args, **kwargs)\n",
      "    File \"D:\\Anaconda\\lib\\site-packages\\keras\\engine\\training.py\", line 557, in __call__\n",
      "      return super().__call__(*args, **kwargs)\n",
      "    File \"D:\\Anaconda\\lib\\site-packages\\keras\\utils\\traceback_utils.py\", line 65, in error_handler\n",
      "      return fn(*args, **kwargs)\n",
      "    File \"D:\\Anaconda\\lib\\site-packages\\keras\\engine\\base_layer.py\", line 1097, in __call__\n",
      "      outputs = call_fn(inputs, *args, **kwargs)\n",
      "    File \"D:\\Anaconda\\lib\\site-packages\\keras\\utils\\traceback_utils.py\", line 96, in error_handler\n",
      "      return fn(*args, **kwargs)\n",
      "    File \"D:\\Anaconda\\lib\\site-packages\\keras\\engine\\sequential.py\", line 410, in call\n",
      "      return super().call(inputs, training=training, mask=mask)\n",
      "    File \"D:\\Anaconda\\lib\\site-packages\\keras\\engine\\functional.py\", line 510, in call\n",
      "      return self._run_internal_graph(inputs, training=training, mask=mask)\n",
      "    File \"D:\\Anaconda\\lib\\site-packages\\keras\\engine\\functional.py\", line 667, in _run_internal_graph\n",
      "      outputs = node.layer(*args, **kwargs)\n",
      "    File \"D:\\Anaconda\\lib\\site-packages\\keras\\utils\\traceback_utils.py\", line 65, in error_handler\n",
      "      return fn(*args, **kwargs)\n",
      "    File \"D:\\Anaconda\\lib\\site-packages\\keras\\engine\\base_layer.py\", line 1097, in __call__\n",
      "      outputs = call_fn(inputs, *args, **kwargs)\n",
      "    File \"D:\\Anaconda\\lib\\site-packages\\keras\\utils\\traceback_utils.py\", line 96, in error_handler\n",
      "      return fn(*args, **kwargs)\n",
      "    File \"D:\\Anaconda\\lib\\site-packages\\keras\\layers\\convolutional\\base_conv.py\", line 314, in call\n",
      "      return self.activation(outputs)\n",
      "    File \"D:\\Anaconda\\lib\\site-packages\\keras\\activations.py\", line 317, in relu\n",
      "      return backend.relu(\n",
      "    File \"D:\\Anaconda\\lib\\site-packages\\keras\\backend.py\", line 5366, in relu\n",
      "      x = tf.nn.relu(x)\n",
      "Node: 'sequential_1/conv2d_4/Relu'\n",
      "input depth must be evenly divisible by filter depth: 4 vs 3\n",
      "\t [[{{node sequential_1/conv2d_4/Relu}}]] [Op:__inference_predict_function_12822]\n",
      "Exception in Tkinter callback\n",
      "Traceback (most recent call last):\n",
      "  File \"D:\\Anaconda\\lib\\tkinter\\__init__.py\", line 1892, in __call__\n",
      "    return self.func(*args)\n",
      "  File \"C:\\Users\\yako_\\AppData\\Local\\Temp\\ipykernel_11484\\1218884212.py\", line 76, in <lambda>\n",
      "    classify_b=Button(top,text=\"Classify Image\",command=lambda: classify(file_path),padx=10,pady=5)\n",
      "  File \"C:\\Users\\yako_\\AppData\\Local\\Temp\\ipykernel_11484\\1218884212.py\", line 70, in classify\n",
      "    pred = np.argmax(model.predict(image),axis=1)\n",
      "  File \"D:\\Anaconda\\lib\\site-packages\\keras\\utils\\traceback_utils.py\", line 70, in error_handler\n",
      "    raise e.with_traceback(filtered_tb) from None\n",
      "  File \"D:\\Anaconda\\lib\\site-packages\\tensorflow\\python\\eager\\execute.py\", line 54, in quick_execute\n",
      "    tensors = pywrap_tfe.TFE_Py_Execute(ctx._handle, device_name, op_name,\n",
      "tensorflow.python.framework.errors_impl.InvalidArgumentError: Graph execution error:\n",
      "\n",
      "Detected at node 'sequential_1/conv2d_4/Relu' defined at (most recent call last):\n",
      "    File \"D:\\Anaconda\\lib\\runpy.py\", line 197, in _run_module_as_main\n",
      "      return _run_code(code, main_globals, None,\n",
      "    File \"D:\\Anaconda\\lib\\runpy.py\", line 87, in _run_code\n",
      "      exec(code, run_globals)\n",
      "    File \"D:\\Anaconda\\lib\\site-packages\\ipykernel_launcher.py\", line 16, in <module>\n",
      "      app.launch_new_instance()\n",
      "    File \"D:\\Anaconda\\lib\\site-packages\\traitlets\\config\\application.py\", line 846, in launch_instance\n",
      "      app.start()\n",
      "    File \"D:\\Anaconda\\lib\\site-packages\\ipykernel\\kernelapp.py\", line 677, in start\n",
      "      self.io_loop.start()\n",
      "    File \"D:\\Anaconda\\lib\\site-packages\\tornado\\platform\\asyncio.py\", line 199, in start\n",
      "      self.asyncio_loop.run_forever()\n",
      "    File \"D:\\Anaconda\\lib\\asyncio\\base_events.py\", line 601, in run_forever\n",
      "      self._run_once()\n",
      "    File \"D:\\Anaconda\\lib\\asyncio\\base_events.py\", line 1905, in _run_once\n",
      "      handle._run()\n",
      "    File \"D:\\Anaconda\\lib\\asyncio\\events.py\", line 80, in _run\n",
      "      self._context.run(self._callback, *self._args)\n",
      "    File \"D:\\Anaconda\\lib\\site-packages\\ipykernel\\kernelbase.py\", line 471, in dispatch_queue\n",
      "      await self.process_one()\n",
      "    File \"D:\\Anaconda\\lib\\site-packages\\ipykernel\\kernelbase.py\", line 460, in process_one\n",
      "      await dispatch(*args)\n",
      "    File \"D:\\Anaconda\\lib\\site-packages\\ipykernel\\kernelbase.py\", line 367, in dispatch_shell\n",
      "      await result\n",
      "    File \"D:\\Anaconda\\lib\\site-packages\\ipykernel\\kernelbase.py\", line 662, in execute_request\n",
      "      reply_content = await reply_content\n",
      "    File \"D:\\Anaconda\\lib\\site-packages\\ipykernel\\ipkernel.py\", line 360, in do_execute\n",
      "      res = shell.run_cell(code, store_history=store_history, silent=silent)\n",
      "    File \"D:\\Anaconda\\lib\\site-packages\\ipykernel\\zmqshell.py\", line 532, in run_cell\n",
      "      return super().run_cell(*args, **kwargs)\n",
      "    File \"D:\\Anaconda\\lib\\site-packages\\IPython\\core\\interactiveshell.py\", line 2863, in run_cell\n",
      "      result = self._run_cell(\n",
      "    File \"D:\\Anaconda\\lib\\site-packages\\IPython\\core\\interactiveshell.py\", line 2909, in _run_cell\n",
      "      return runner(coro)\n",
      "    File \"D:\\Anaconda\\lib\\site-packages\\IPython\\core\\async_helpers.py\", line 129, in _pseudo_sync_runner\n",
      "      coro.send(None)\n",
      "    File \"D:\\Anaconda\\lib\\site-packages\\IPython\\core\\interactiveshell.py\", line 3106, in run_cell_async\n",
      "      has_raised = await self.run_ast_nodes(code_ast.body, cell_name,\n",
      "    File \"D:\\Anaconda\\lib\\site-packages\\IPython\\core\\interactiveshell.py\", line 3309, in run_ast_nodes\n",
      "      if await self.run_code(code, result, async_=asy):\n",
      "    File \"D:\\Anaconda\\lib\\site-packages\\IPython\\core\\interactiveshell.py\", line 3369, in run_code\n",
      "      exec(code_obj, self.user_global_ns, self.user_ns)\n",
      "    File \"C:\\Users\\yako_\\AppData\\Local\\Temp\\ipykernel_11484\\1218884212.py\", line 104, in <cell line: 104>\n",
      "      top.mainloop()\n",
      "    File \"D:\\Anaconda\\lib\\tkinter\\__init__.py\", line 1429, in mainloop\n",
      "      self.tk.mainloop(n)\n",
      "    File \"D:\\Anaconda\\lib\\tkinter\\__init__.py\", line 1892, in __call__\n",
      "      return self.func(*args)\n",
      "    File \"C:\\Users\\yako_\\AppData\\Local\\Temp\\ipykernel_11484\\1218884212.py\", line 76, in <lambda>\n",
      "      classify_b=Button(top,text=\"Classify Image\",command=lambda: classify(file_path),padx=10,pady=5)\n",
      "    File \"C:\\Users\\yako_\\AppData\\Local\\Temp\\ipykernel_11484\\1218884212.py\", line 70, in classify\n",
      "      pred = np.argmax(model.predict(image),axis=1)\n",
      "    File \"D:\\Anaconda\\lib\\site-packages\\keras\\utils\\traceback_utils.py\", line 65, in error_handler\n",
      "      return fn(*args, **kwargs)\n",
      "    File \"D:\\Anaconda\\lib\\site-packages\\keras\\engine\\training.py\", line 2253, in predict\n",
      "      tmp_batch_outputs = self.predict_function(iterator)\n",
      "    File \"D:\\Anaconda\\lib\\site-packages\\keras\\engine\\training.py\", line 2041, in predict_function\n",
      "      return step_function(self, iterator)\n",
      "    File \"D:\\Anaconda\\lib\\site-packages\\keras\\engine\\training.py\", line 2027, in step_function\n",
      "      outputs = model.distribute_strategy.run(run_step, args=(data,))\n",
      "    File \"D:\\Anaconda\\lib\\site-packages\\keras\\engine\\training.py\", line 2015, in run_step\n",
      "      outputs = model.predict_step(data)\n",
      "    File \"D:\\Anaconda\\lib\\site-packages\\keras\\engine\\training.py\", line 1983, in predict_step\n",
      "      return self(x, training=False)\n",
      "    File \"D:\\Anaconda\\lib\\site-packages\\keras\\utils\\traceback_utils.py\", line 65, in error_handler\n",
      "      return fn(*args, **kwargs)\n",
      "    File \"D:\\Anaconda\\lib\\site-packages\\keras\\engine\\training.py\", line 557, in __call__\n",
      "      return super().__call__(*args, **kwargs)\n",
      "    File \"D:\\Anaconda\\lib\\site-packages\\keras\\utils\\traceback_utils.py\", line 65, in error_handler\n",
      "      return fn(*args, **kwargs)\n",
      "    File \"D:\\Anaconda\\lib\\site-packages\\keras\\engine\\base_layer.py\", line 1097, in __call__\n",
      "      outputs = call_fn(inputs, *args, **kwargs)\n",
      "    File \"D:\\Anaconda\\lib\\site-packages\\keras\\utils\\traceback_utils.py\", line 96, in error_handler\n",
      "      return fn(*args, **kwargs)\n",
      "    File \"D:\\Anaconda\\lib\\site-packages\\keras\\engine\\sequential.py\", line 410, in call\n",
      "      return super().call(inputs, training=training, mask=mask)\n",
      "    File \"D:\\Anaconda\\lib\\site-packages\\keras\\engine\\functional.py\", line 510, in call\n",
      "      return self._run_internal_graph(inputs, training=training, mask=mask)\n",
      "    File \"D:\\Anaconda\\lib\\site-packages\\keras\\engine\\functional.py\", line 667, in _run_internal_graph\n",
      "      outputs = node.layer(*args, **kwargs)\n",
      "    File \"D:\\Anaconda\\lib\\site-packages\\keras\\utils\\traceback_utils.py\", line 65, in error_handler\n",
      "      return fn(*args, **kwargs)\n",
      "    File \"D:\\Anaconda\\lib\\site-packages\\keras\\engine\\base_layer.py\", line 1097, in __call__\n",
      "      outputs = call_fn(inputs, *args, **kwargs)\n",
      "    File \"D:\\Anaconda\\lib\\site-packages\\keras\\utils\\traceback_utils.py\", line 96, in error_handler\n",
      "      return fn(*args, **kwargs)\n",
      "    File \"D:\\Anaconda\\lib\\site-packages\\keras\\layers\\convolutional\\base_conv.py\", line 314, in call\n",
      "      return self.activation(outputs)\n",
      "    File \"D:\\Anaconda\\lib\\site-packages\\keras\\activations.py\", line 317, in relu\n",
      "      return backend.relu(\n",
      "    File \"D:\\Anaconda\\lib\\site-packages\\keras\\backend.py\", line 5366, in relu\n",
      "      x = tf.nn.relu(x)\n",
      "Node: 'sequential_1/conv2d_4/Relu'\n",
      "input depth must be evenly divisible by filter depth: 4 vs 3\n",
      "\t [[{{node sequential_1/conv2d_4/Relu}}]] [Op:__inference_predict_function_12822]\n"
     ]
    },
    {
     "name": "stdout",
     "output_type": "stream",
     "text": [
      "1/1 [==============================] - 0s 32ms/step\n",
      "Right-of-way at intersection\n",
      "1/1 [==============================] - 0s 36ms/step\n",
      "Right-of-way at intersection\n",
      "1/1 [==============================] - 0s 33ms/step\n",
      "Pedestrians\n",
      "1/1 [==============================] - 0s 36ms/step\n",
      "Pedestrians\n",
      "1/1 [==============================] - 0s 32ms/step\n",
      "Speed limit (20km/h)\n",
      "1/1 [==============================] - 0s 33ms/step\n",
      "Speed limit (20km/h)\n",
      "1/1 [==============================] - 0s 36ms/step\n",
      "Speed limit (20km/h)\n",
      "1/1 [==============================] - 0s 32ms/step\n",
      "Pedestrians\n",
      "1/1 [==============================] - 0s 33ms/step\n",
      "Pedestrians\n",
      "1/1 [==============================] - 0s 43ms/step\n",
      "Pedestrians\n",
      "1/1 [==============================] - 0s 33ms/step\n",
      "Priority road\n"
     ]
    }
   ],
   "source": [
    "import tkinter as tk\n",
    "from tkinter import filedialog\n",
    "from tkinter import *\n",
    "from PIL import ImageTk,Image\n",
    "import numpy as np\n",
    "\n",
    "from keras.models import load_model\n",
    "model=load_model(\"gtsrb_classifier.h5\")\n",
    "\n",
    "classes={\n",
    "    1:\"Speed limit (20km/h)\",\n",
    "    2:'Speed limit (30km/h)', \n",
    "    3:'Speed limit (50km/h)', \n",
    "    4:'Speed limit (60km/h)', \n",
    "    5:'Speed limit (70km/h)', \n",
    "    6:'Speed limit (80km/h)', \n",
    "    7:'End of speed limit (80km/h)', \n",
    "    8:'Speed limit (100km/h)', \n",
    "    9:'Speed limit (120km/h)', \n",
    "    10:'No passing', \n",
    "    11:'No passing veh over 3.5 tons', \n",
    "    12:'Right-of-way at intersection', \n",
    "    13:'Priority road', \n",
    "    14:'Yield', \n",
    "    15:'Stop', \n",
    "    16:'No vehicles', \n",
    "    17:'Veh > 3.5 tons prohibited', \n",
    "    18:'No entry', \n",
    "    19:'General caution', \n",
    "    20:'Dangerous curve left', \n",
    "    21:'Dangerous curve right', \n",
    "    22:'Double curve', \n",
    "    23:'Bumpy road', \n",
    "    24:'Slippery road', \n",
    "    25:'Road narrows on the right', \n",
    "    26:'Road work', \n",
    "    27:'Traffic signals', \n",
    "    28:'Pedestrians', \n",
    "    29:'Children crossing', \n",
    "    30:'Bicycles crossing', \n",
    "    31:'Beware of ice/snow',\n",
    "    32:'Wild animals crossing', \n",
    "    33:'End speed + passing limits', \n",
    "    34:'Turn right ahead', \n",
    "    35:'Turn left ahead', \n",
    "    36:'Ahead only', \n",
    "    37:'Go straight or right', \n",
    "    38:'Go straight or left', \n",
    "    39:'Keep right', \n",
    "    40:'Keep left', \n",
    "    41:'Roundabout mandatory', \n",
    "    42:'End of no passing', \n",
    "    43:'End no passing veh > 3.5 tons'\n",
    "}\n",
    "\n",
    "top=tk.Tk()\n",
    "top.geometry(\"800x600\")\n",
    "top.title(\"Image Classification CIFAR 10\")\n",
    "top.configure(background=\"#CDCDCD\")\n",
    "label=Label(top,background=\"#CDCDCD\",font=(\"arial\",15,\"bold\"))\n",
    "sign_image=Label(top)\n",
    "\n",
    "def classify(file_path):\n",
    "    \n",
    "    global label_packed\n",
    "    image=Image.open(file_path)\n",
    "    image=image.resize((32,32))\n",
    "    image=np.expand_dims(image,axis=0)\n",
    "    image=np.array(image)\n",
    "    pred = np.argmax(model.predict(image),axis=1)\n",
    "    sign=classes[pred[0]]\n",
    "    print(sign)\n",
    "    label.configure(foreground=\"#011638\",text=sign)\n",
    "\n",
    "def show_classify_button(file_path):\n",
    "    classify_b=Button(top,text=\"Classify Image\",command=lambda: classify(file_path),padx=10,pady=5)\n",
    "    classify_b.configure(background=\"#364156\",foreground=\"white\",font=(\"arial\",9,\"bold\"))\n",
    "    classify_b.place(relx=0.79,rely=0.46)\n",
    "\n",
    "def upload_image():\n",
    "    try:\n",
    "        file_path=filedialog.askopenfilename()\n",
    "        uploaded=Image.open(file_path)\n",
    "        uploaded.thumbnail(((top.winfo_width()/2.25),(top.winfo_height()/2.25)))\n",
    "        im=ImageTk.PhotoImage(uploaded)\n",
    "        sign_image.configure(image=im)\n",
    "        sign_image.image=im\n",
    "        label.configure(text=\"\")\n",
    "        show_classify_button(file_path)\n",
    "    except:\n",
    "        pass\n",
    "\n",
    "upload=Button(top,text=\"Upload an Image\",command=upload_image,padx=10,pady=5)\n",
    "\n",
    "upload.configure(background=\"#364156\",foreground=\"white\",font=(\"arial\",10,\"bold\"))\n",
    "\n",
    "upload.pack(side=BOTTOM,pady=50)\n",
    "sign_image.pack(side=BOTTOM,expand=True)\n",
    "label.pack(side=BOTTOM,expand=True)\n",
    "heading=Label(top,text=\"Image Classification CIFAR 10\",pady=20,font=(\"arial\",20,\"bold\"))\n",
    "\n",
    "heading.configure(background=\"#CDCDCD\",foreground=\"#364156\")\n",
    "heading.pack()\n",
    "top.mainloop()"
   ]
  },
  {
   "cell_type": "code",
   "execution_count": null,
   "id": "45f3823a",
   "metadata": {},
   "outputs": [],
   "source": []
  },
  {
   "cell_type": "code",
   "execution_count": null,
   "id": "796d5388",
   "metadata": {},
   "outputs": [],
   "source": []
  }
 ],
 "metadata": {
  "kernelspec": {
   "display_name": "Python 3 (ipykernel)",
   "language": "python",
   "name": "python3"
  },
  "language_info": {
   "codemirror_mode": {
    "name": "ipython",
    "version": 3
   },
   "file_extension": ".py",
   "mimetype": "text/x-python",
   "name": "python",
   "nbconvert_exporter": "python",
   "pygments_lexer": "ipython3",
   "version": "3.9.12"
  },
  "toc": {
   "base_numbering": 1,
   "nav_menu": {},
   "number_sections": true,
   "sideBar": true,
   "skip_h1_title": false,
   "title_cell": "Table of Contents",
   "title_sidebar": "Contents",
   "toc_cell": false,
   "toc_position": {},
   "toc_section_display": true,
   "toc_window_display": false
  },
  "varInspector": {
   "cols": {
    "lenName": 16,
    "lenType": 16,
    "lenVar": 40
   },
   "kernels_config": {
    "python": {
     "delete_cmd_postfix": "",
     "delete_cmd_prefix": "del ",
     "library": "var_list.py",
     "varRefreshCmd": "print(var_dic_list())"
    },
    "r": {
     "delete_cmd_postfix": ") ",
     "delete_cmd_prefix": "rm(",
     "library": "var_list.r",
     "varRefreshCmd": "cat(var_dic_list()) "
    }
   },
   "types_to_exclude": [
    "module",
    "function",
    "builtin_function_or_method",
    "instance",
    "_Feature"
   ],
   "window_display": false
  }
 },
 "nbformat": 4,
 "nbformat_minor": 5
}
